<mujoco model='Franka'>
    <compiler inertiafromgeom='true' angle='radian' meshdir='meshes' fitaabb='true' />

    <default>
        <joint limited='true' damping='10' armature='0.001' axis='0 0 1' type='hinge'/>
        <geom contype='1' conaffinity='1' condim='1' rgba='0.8 0.6 .4 1'
        	margin='0.001' solref='.02 1' solimp='.8 .8 .01' material='geom'/>
        <motor ctrlrange='-1.0 1.0' ctrllimited='true' forcelimited='true' forcerange='-100 100'/>
        <position ctrlrange='-1.0 1.0' ctrllimited='true' forcelimited='true' forcerange='-100 100'/>

        <default class='collision'>
          <!-- <geom group='0' type='capsule' fitscale='1.2' contype='1' conaffinity='0' /> -->
          <geom group='3' type='mesh' contype='1' conaffinity='0' />
        </default>
        <default class='visual'>
          <geom group='0' type='mesh' contype='0' conaffinity='0' material='robot' />
        </default>
    </default>

    <option timestep='0.002' iterations='50' tolerance='1e-10' solver='Newton' jacobian='dense' cone='elliptic'/>

    <size nstack='1000000'/>

    <visual>
        <map fogstart='3' fogend='5' force='0.1' znear='0.5'/>
        <quality shadowsize='2048' offsamples='8'/>
        <global offwidth='800' offheight='800'/>
    </visual>

    <asset>
        <texture type='skybox' builtin='gradient' width='128' height='128' rgb1='.4 .6 .8' 
            rgb2='0 0 0'/>  
        <texture name='texgeom' type='cube' builtin='flat' mark='cross' width='127' height='1278' 
            rgb1='0.8 0.6 0.4' rgb2='0.8 0.6 0.4' markrgb='1 1 1' random='0.01'/>  
        <texture name='texplane' type='2d' builtin='checker' rgb1='.2 .3 .4' rgb2='.1 0.15 0.2' 
            width='512' height='512'/>  

        <material name='MatPlane' reflectance='0.3' texture='texplane' texrepeat='1 1' texuniform='true'/>
        <material name='geom' texture='texgeom' texuniform='true'/>
        <material name='robot' rgba='0.8 0.8 0.8 1' specular='0.8' shininess='0.1'/>

        <mesh name='col_finger' file='collision/finger.stl'/>
        <mesh name='col_hand'   file='collision/hand.stl'/>
        <mesh name='col_link0'  file='collision/link0.stl'/>
        <mesh name='col_link1'  file='collision/link1.stl'/>
        <mesh name='col_link2'  file='collision/link2.stl'/>
        <mesh name='col_link3'  file='collision/link3.stl'/>
        <mesh name='col_link4'  file='collision/link4.stl'/>
        <mesh name='col_link5'  file='collision/link5.stl'/>
        <mesh name='col_link6'  file='collision/link6.stl'/>
        <mesh name='col_link7'  file='collision/link7.stl'/>
        <mesh name='viz_finger' file='visual/finger.stl' refquat='1 -1 0 0'/>
        <mesh name='viz_hand'   file='visual/hand.stl' refquat='1 -1 0 0'/>
        <mesh name='viz_link0'  file='visual/link0.stl' refquat='1 -1 0 0'/>
        <mesh name='viz_link1'  file='visual/link1.stl' refquat='1 -1 0 0'/>
        <mesh name='viz_link2'  file='visual/link2.stl' refquat='1 -1 0 0'/>
        <mesh name='viz_link3'  file='visual/link3.stl' refquat='1 -1 0 0'/>
        <mesh name='viz_link4'  file='visual/link4.stl' refquat='1 -1 0 0'/>
        <mesh name='viz_link5'  file='visual/link5.stl' refquat='1 -1 0 0'/>
        <mesh name='viz_link6'  file='visual/link6.stl' refquat='1 -1 0 0'/>
        <mesh name='viz_link7'  file='visual/link7.stl' refquat='1 -1 0 0'/>
    </asset>

    <worldbody>
      <geom name='floor' pos='0 0 0' size='5 5 .125' type='plane' material='MatPlane' condim='3'/>

      <light mode='targetbodycom' target='link0' directional='false' diffuse='.8 .8 .8' specular='0.3 0.3 0.3' pos='0 0 4.0' dir='0 0 -1'/>

      <body name='link0' pos='0 0 0'>
        <geom name='link0' mesh='col_link0' class='collision'/>
        <geom name='vlink0' mesh='viz_link0' class='visual'/>
        <body name='link1' pos='0 0 0.333'>
          <joint name='joint1' pos='0 0 -0.333' range='-2.8973 2.8973' />
          <geom name='link1' mesh='col_link1' class='collision'/>
          <geom name='vlink1' mesh='viz_link1' class='visual'/>
          <body name='link2' pos='0 0 0' euler='-1.5707 0 0' >
            <joint name='joint2' pos='0 0 0' range='-1.7628 1.7628' />
            <geom name='link2' mesh='col_link2' class='collision'/>
            <geom name='vlink2' mesh='viz_link2' class='visual'/>
            <body name='link3' pos='0 -0.316 0' euler='1.5707 0 0' >
              <joint name='joint3' pos='0 0 -0.12' range='-2.8973 2.8973' />
              <geom name='link3' mesh='col_link3' class='collision'/>
              <geom name='vlink3' mesh='viz_link3' class='visual'/>
              <body name='link4' pos='0.0825 0 0' euler='1.5707 0 0' >
                <joint name='joint4' pos='0 0 0' range='-3.0718 0.0698' />
                <geom name='link4' mesh='col_link4' class='collision'/>
                <geom name='vlink4' mesh='viz_link4' class='visual'/>
                <body name='link5' pos='-0.0825 0.384 0' euler='-1.5707 0 0' >
                  <joint name='joint5' pos='0 0 -0.26' range='-2.8973 2.9873' />
                  <geom name='link5' mesh='col_link5' class='collision'/>
                  <geom name='vlink5' mesh='viz_link5' class='visual'/>
                  <body name='link6' pos='0 0 0' euler='1.5707 0 0' >
                    <joint name='joint6' pos='0 0 0' range='-0.0175 3.7525' />
                    <geom name='link6' mesh='col_link6' class='collision'/>
                    <geom name='vlink6' mesh='viz_link6' class='visual'/>
                    <body name='link7' pos='0.088 0 0' euler='1.5707 0 0' >
                      <joint name='joint7' pos='0 0 0' range='-2.8973 2.9873' />
                      <geom name='link7' mesh='col_link7' class='collision'/>
                      <geom name='vlink7' mesh='viz_link7' class='visual'/>

                      <!-- Hand Start-->
                      <body name='hand' pos='0 0 0.107' euler='0 0 0' >
                        <geom name='hand' mesh='col_hand' class='collision'/>
                        <geom name='vhand' mesh='viz_hand' class='visual'/>
                        <site name='hand' pos='0 0 0.103' type='sphere' size='0.01' rgba='0.1 0.1 0.1 0.5' />
                        <body name='finger1' pos='0 0 0.0584' euler='0 0 0' >
                          <joint name='finger1' type='slide' axis='0 1 0' pos='0 0 0' range='0.0 0.04' />
                          <geom name='finger1' mesh='col_finger' class='collision'/>
                          <geom name='vfinger1' mesh='viz_finger' class='visual'/>
                        </body>
                        <body name='finger2' pos='0 0 0.0584' euler='0 0 -3.1415' >
                          <joint name='finger2' type='slide' axis='0 -1 0' pos='0 0 0' range='-0.04 0' />
                          <geom name='finger2' mesh='col_finger' class='collision'/>
                          <geom name='vfinger2' mesh='viz_finger' class='visual'/>
                        </body>
                      </body>
                      <!-- Hand End -->

                    </body>
                  </body>
                </body>
              </body>
            </body>
          </body>
        </body>
      </body>
      <body name='box_body' pos='0.6 0 0.015'>
        <freejoint/>
        <geom group='1' size='0.015 0.015 0.015' type='box' name='mybox' rgba='1 0 0 1' mass='0.1' contype='1' conaffinity='1' />
      </body>
    </worldbody>

    <equality>
      <!-- Links default hand grippers together -->
      <joint name='finger2' joint1='finger1' joint2='finger2' polycoef='0 -1 0 0 0' />
    </equality>

    <actuator>
      <position name='joint1' kp='107' joint='joint1' ctrllimited='true' ctrlrange='-2.8 2.8'/>
      <position name='joint2' kp='107' joint='joint2' ctrllimited='true' ctrlrange='-1.7 1.7'/>
      <position name='joint3' kp='107' joint='joint3' ctrllimited='true' ctrlrange='-2.8 2.8'/>
      <position name='joint4' kp='107' joint='joint4' ctrllimited='true' ctrlrange='-3 0'/>
      <position name='joint5' kp='51' joint='joint5'  ctrllimited='true' ctrlrange='-2.8 2.9'/>
      <position name='joint6' kp='51' joint='joint6'  ctrllimited='true' ctrlrange='-0 3.7'/>
      <position name='joint7' kp='51' joint='joint7'  ctrllimited='true' ctrlrange='-2.8 2.9'/>
      <position name='finger' kp='20' joint='finger1' ctrllimited='true' ctrlrange='-0.04 0.04'/>

      <velocity name='vjoint1' kv='18' joint='joint1'  ctrllimited='true' ctrlrange='-0.001 0.001'/>
      <velocity name='vjoint2' kv='18' joint='joint2'  ctrllimited='true' ctrlrange='-0.001 0.001'/>
      <velocity name='vjoint3' kv='18' joint='joint3'  ctrllimited='true' ctrlrange='-0.001 0.001'/>
      <velocity name='vjoint4' kv='18' joint='joint4'  ctrllimited='true' ctrlrange='-0.001 0.001'/>
      <velocity name='vjoint5' kv='15' joint='joint5'  ctrllimited='true' ctrlrange='-0.001 0.001'/>
      <velocity name='vjoint6' kv='15' joint='joint6'  ctrllimited='true' ctrlrange='-0.001 0.001'/>
      <velocity name='vjoint7' kv='15' joint='joint7'  ctrllimited='true' ctrlrange='-0.001 0.001'/>
      <velocity name='vfinger' kv='2' joint='finger1' ctrllimited='true' ctrlrange='-0.001 0.001'/>

      <!--
      <motor name='joint1' gear='87' joint='joint1' />
      <motor name='joint2' gear='87' joint='joint2' />
      <motor name='joint3' gear='87' joint='joint3' />
      <motor name='joint4' gear='87' joint='joint4' />
      <motor name='joint5' gear='12' joint='joint5' />
      <motor name='joint6' gear='12' joint='joint6' />
      <motor name='joint7' gear='12' joint='joint7' />
      <motor name='finger' gear='20' joint='finger1' />
      -->
    </actuator>

    <keyframe>
      <key qpos='0 0.3 0 -1.2 0 1.6 0.0 0.04 -0.04      0.6 0 0.015 1 0 0 0'/>
    </keyframe>
  </mujoco>

